Workbook

Sheet Experiment
A1: Name: | B1: Gabe Wilson | AD1: Number: | AE1: Well Type: | AF1: Condition: | AG1: Samples/Well:
A2: Notebook Code: | B2: GW0826 | AD2: 1 | AE2: Condition | AF2: 1 | AG2: 1 | AI2: A long set of instructions:
A3: Experiment Name: | B3: Test experiment | AD3: 2 | AE3: Condition | AF3: 2 | AG3: 1 | AU3: "Before" indicates that this number of the condition selected should be run before all of the samples. Likewise with "after" referring to after all samples are run. "Between" counts indicate the number runs of this condition to be put into blocks that will be inserted at intervals between blocks of sample.
AD4: 3 | AE4: Condition | AF4: 3 | AG4: 1
A5: Plate color: | B5: Plate name: | D5: Plate 1 | E5: 1 | F5: 2 | G5: 3 | H5: 4 | I5: 5 | J5: 6 | K5: 7 | L5: 8 | M5: 9 | N5: 10 | O5: 11 | P5: 12 | Q5: 13 | R5: 14 | S5: 15 | T5: 16 | U5: 17 | V5: 18 | W5: 19 | X5: 20 | Y5: 21 | Z5: 22 | AA5: 23 | AB5: 24 | AD5: 4 | AE5: Condition | AF5: 4 | AG5: 1
A6: R | B6: Gonda | D6: A | E6: 32 | AD6: 5 | AE6: Condition | AF6: 5 | AG6: 1
D7: B | F7: 31 | G7: 31 | H7: 31 | I7: 31 | J7: 31 | M7: 1 | N7: 1 | O7: 1 | P7: 1 | Q7: 1 | S7: 16 | T7: 16 | U7: 16 | V7: 16 | W7: 16 | AD7: 6 | AE7: Condition | AF7: 6 | AG7: 1
D8: C | F8: 31 | G8: 31 | H8: 31 | I8: 31 | J8: 31 | M8: 2 | N8: 2 | O8: 2 | P8: 2 | Q8: 2 | S8: 17 | T8: 17 | U8: 17 | V8: 17 | W8: 17 | AD8: 7 | AE8: Condition | AF8: 7 | AG8: 1
D9: D | M9: 3 | N9: 3 | O9: 3 | P9: 3 | Q9: 3 | S9: 18 | T9: 18 | U9: 18 | V9: 18 | W9: 18 | AD9: 8 | AE9: Condition | AF9: 8 | AG9: 1
D10: E | M10: 4 | N10: 4 | O10: 4 | P10: 4 | Q10: 4 | S10: 19 | T10: 19 | U10: 19 | V10: 19 | W10: 19 | AD10: 9 | AE10: Condition | AF10: 9 | AG10: 1
D11: F | M11: 5 | N11: 5 | O11: 5 | P11: 5 | Q11: 5 | S11: 20 | T11: 20 | U11: 20 | V11: 20 | W11: 20 | AD11: 10 | AE11: Condition | AF11: 10 | AG11: 1
D12: G | M12: 6 | N12: 6 | O12: 6 | P12: 6 | Q12: 6 | S12: 21 | T12: 21 | U12: 21 | V12: 21 | W12: 21 | AD12: 11 | AE12: Condition | AF12: 11 | AG12: 1
D13: H | M13: 7 | N13: 7 | O13: 7 | P13: 7 | Q13: 7 | S13: 22 | T13: 22 | U13: 22 | V13: 22 | W13: 22 | AD13: 12 | AE13: Condition | AF13: 12 | AG13: 1
D14: I | M14: 8 | N14: 8 | O14: 8 | P14: 8 | Q14: 8 | S14: 23 | T14: 23 | U14: 23 | V14: 23 | W14: 23 | AD14: 13 | AE14: Condition | AF14: 13 | AG14: 1
D15: J | M15: 9 | N15: 9 | O15: 9 | P15: 9 | Q15: 9 | S15: 24 | T15: 24 | U15: 24 | V15: 24 | W15: 24 | AD15: 14 | AE15: Condition | AF15: 14 | AG15: 1
D16: K | M16: 10 | N16: 10 | O16: 10 | P16: 10 | Q16: 10 | S16: 25 | T16: 25 | U16: 25 | V16: 25 | W16: 25 | AD16: 15 | AE16: Condition | AF16: 15 | AG16: 1
D17: L | M17: 11 | N17: 11 | O17: 11 | P17: 11 | Q17: 11 | S17: 26 | T17: 26 | U17: 26 | V17: 26 | W17: 26 | AD17: 16 | AE17: Condition | AF17: 16 | AG17: 1
D18: M | M18: 12 | N18: 12 | O18: 12 | P18: 12 | Q18: 12 | S18: 27 | T18: 27 | U18: 27 | V18: 27 | W18: 27 | AD18: 17 | AE18: Condition | AF18: 17 | AG18: 1
D19: N | M19: 13 | N19: 13 | O19: 13 | P19: 13 | Q19: 13 | S19: 28 | T19: 28 | U19: 28 | V19: 28 | W19: 28 | AD19: 18 | AE19: Condition | AF19: 18 | AG19: 1
D20: O | M20: 14 | N20: 14 | O20: 14 | P20: 14 | Q20: 14 | S20: 29 | T20: 29 | U20: 29 | V20: 29 | W20: 29 | AD20: 19 | AE20: Condition | AF20: 19 | AG20: 1
D21: P | M21: 15 | N21: 15 | O21: 15 | P21: 15 | Q21: 15 | S21: 30 | T21: 30 | U21: 30 | V21: 30 | W21: 30 | AD21: 20 | AE21: Condition | AF21: 20 | AG21: 1
AD22: 21 | AE22: Condition | AF22: 21 | AG22: 1
A23: Plate color: | B23: Plate name: | D23: Plate 2 | E23: 1 | F23: 2 | G23: 3 | H23: 4 | I23: 5 | J23: 6 | K23: 7 | L23: 8 | M23: 9 | N23: 10 | O23: 11 | P23: 12 | Q23: 13 | R23: 14 | S23: 15 | T23: 16 | U23: 17 | V23: 18 | W23: 19 | X23: 20 | Y23: 21 | Z23: 22 | AA23: 23 | AB23: 24 | AD23: 22 | AE23: Condition | AF23: 22 | AG23: 1
D24: A | AD24: 23 | AE24: Condition | AF24: 23 | AG24: 1
D25: B | AD25: 24 | AE25: Condition | AF25: 24 | AG25: 1
D26: C | AD26: 25 | AE26: Condition | AF26: 25 | AG26: 1
D27: D | AD27: 26 | AE27: Condition | AF27: 26 | AG27: 1
D28: E | AD28: 27 | AE28: Condition | AF28: 27 | AG28: 1
D29: F | AD29: 28 | AE29: Condition | AF29: 28 | AG29: 1
D30: G | AD30: 29 | AE30: Condition | AF30: 29 | AG30: 1
D31: H | AD31: 30 | AE31: QC | AF31: 30 | AG31: 1
D32: I | AD32: 31 | AE32: WetQC | AF32: QC | AG32: 3
D33: J | AD33: 32 | AE33: TrueBlank | AF33: TrueBlank | AG33: 1 | AI33: Force even blocks? | AJ33: No | AK33: Doesn't use all wells in order to create blocks of the same size.
D34: K | AD34: 33 | AE34: Condition | AF34: 67 | AG34: 1 | AI34: TrueBlank Well Location | AJ34: RA25
D35: L | AD35: 34
D36: M | AD36: 35 | AI36: Experiment One | AJ36: All | AK36: Either write "All" for experiment one or a number range corresponding to the Number (AD) column. For example "1-3" and "4-6".
D37: N | AD37: 36 | AI37: Experiment Two
D38: O | AD38: 37 | AI38: Are libraries the same between experiments? | AJ38: Yes
D39: P | AD39: 38
AD40: 39
...

Sheet Machine
A1: Number: | B1: Well Type: | C1: Condition: | D1: MS DataPath: | E1: MS MethodPath: | F1: MS method: | G1: MS method file name: | H1: LC DataPath | I1: LC MethodPath: | J1: LC method: | K1: LC method file name: | L1: Samples/Well: | M1: Number of sample to run: | N1: QC before: | O1: QC after: | P1: QC between:
A2: 1 | B2: =IF(LEN(Experiment!AE2)=0,"",Experiment!AE2) -> Condition | C2: =IF(LEN(Experiment!AF2)=0,"",Experiment!AF2) -> 1 | D2: D:/data/Ximena/Gonda0821 | E2: D:/method/Chao/something | F2: DIA20ng | G2: DIA20ng | H2: C:/data/Ximena/Gonda | I2: lcmethodpath | J2: lcmethodshort_dry | K2: lcmethodfilename | L2: =IF(LEN(Experiment!AG2)=0,"",Experiment!AG2) -> 1 | M2: 3 | Q2: Columns: | R2: 2 column
A3: 2 | B3: =IF(LEN(Experiment!AE3)=0,"",Experiment!AE3) -> Condition | C3: =IF(LEN(Experiment!AF3)=0,"",Experiment!AF3) -> 2 | D3: D:/data/Ximena/Gonda0821 | E3: D:/method/Chao/something | F3: DIA20ng | G3: DIA20ng | H3: C:/data/Ximena/Gonda | I3: lcmethodpath | J3: lcmethodshort_dry | K3: lcmethodfilename | L3: =IF(LEN(Experiment!AG3)=0,"",Experiment!AG3) -> 1 | M3: 3
A4: 3 | B4: =IF(LEN(Experiment!AE4)=0,"",Experiment!AE4) -> Condition | C4: =IF(LEN(Experiment!AF4)=0,"",Experiment!AF4) -> 3 | D4: D:/data/Ximena/Gonda0821 | E4: D:/method/Chao/something | F4: DIA20ng | G4: DIA20ng | H4: C:/data/Ximena/Gonda | I4: lcmethodpath | J4: lcmethodshort_dry | K4: lcmethodfilename | L4: =IF(LEN(Experiment!AG4)=0,"",Experiment!AG4) -> 1 | M4: 3
A5: 4 | B5: =IF(LEN(Experiment!AE5)=0,"",Experiment!AE5) -> Condition | C5: =IF(LEN(Experiment!AF5)=0,"",Experiment!AF5) -> 4 | D5: D:/data/Ximena/Gonda0821 | E5: D:/method/Chao/something | F5: DIA20ng | G5: DIA20ng | H5: C:/data/Ximena/Gonda | I5: lcmethodpath | J5: lcmethodshort_dry | K5: lcmethodfilename | L5: =IF(LEN(Experiment!AG5)=0,"",Experiment!AG5) -> 1 | M5: 3 | Q5: Library value placement | R5: Before
A6: 5 | B6: =IF(LEN(Experiment!AE6)=0,"",Experiment!AE6) -> Condition | C6: =IF(LEN(Experiment!AF6)=0,"",Experiment!AF6) -> 5 | D6: D:/data/Ximena/Gonda0821 | E6: D:/method/Chao/something | F6: DIA20ng | G6: DIA20ng | H6: C:/data/Ximena/Gonda | I6: lcmethodpath | J6: lcmethodshort_dry | K6: lcmethodfilename | L6: =IF(LEN(Experiment!AG6)=0,"",Experiment!AG6) -> 1 | M6: 3 | Q6: Frequency of system validation (#)
A7: 6 | B7: =IF(LEN(Experiment!AE7)=0,"",Experiment!AE7) -> Condition | C7: =IF(LEN(Experiment!AF7)=0,"",Experiment!AF7) -> 6 | D7: D:/data/Ximena/Gonda0821 | E7: D:/method/Chao/something | F7: DIA20ng | G7: DIA20ng | H7: C:/data/Ximena/Gonda | I7: lcmethodpath | J7: lcmethodshort_dry | K7: lcmethodfilename | L7: =IF(LEN(Experiment!AG7)=0,"",Experiment!AG7) -> 1 | M7: 3 | Q7: Frequency of QC | R7: 10
A8: 7 | B8: =IF(LEN(Experiment!AE8)=0,"",Experiment!AE8) -> Condition | C8: =IF(LEN(Experiment!AF8)=0,"",Experiment!AF8) -> 7 | D8: D:/data/Ximena/Gonda0821 | E8: D:/method/Chao/something | F8: DIA20ng | G8: DIA20ng | H8: C:/data/Ximena/Gonda | I8: lcmethodpath | J8: lcmethodshort_dry | K8: lcmethodfilename | L8: =IF(LEN(Experiment!AG8)=0,"",Experiment!AG8) -> 1 | M8: 3
A9: 8 | B9: =IF(LEN(Experiment!AE9)=0,"",Experiment!AE9) -> Condition | C9: =IF(LEN(Experiment!AF9)=0,"",Experiment!AF9) -> 8 | D9: D:/data/Ximena/Gonda0821 | E9: D:/method/Chao/something | F9: DIA20ng | G9: DIA20ng | H9: C:/data/Ximena/Gonda | I9: lcmethodpath | J9: lcmethodshort_dry | K9: lcmethodfilename | L9: =IF(LEN(Experiment!AG9)=0,"",Experiment!AG9) -> 1 | M9: 3
A10: 9 | B10: =IF(LEN(Experiment!AE10)=0,"",Experiment!AE10) -> Condition | C10: =IF(LEN(Experiment!AF10)=0,"",Experiment!AF10) -> 9 | D10: D:/data/Ximena/Gonda0821 | E10: D:/method/Chao/something | F10: DIA20ng | G10: DIA20ng | H10: C:/data/Ximena/Gonda | I10: lcmethodpath | J10: lcmethodshort_dry | K10: lcmethodfilename | L10: =IF(LEN(Experiment!AG10)=0,"",Experiment!AG10) -> 1 | M10: 3
A11: 10 | B11: =IF(LEN(Experiment!AE11)=0,"",Experiment!AE11) -> Condition | C11: =IF(LEN(Experiment!AF11)=0,"",Experiment!AF11) -> 10 | D11: D:/data/Ximena/Gonda0821 | E11: D:/method/Chao/something | F11: DIA20ng | G11: DIA20ng | H11: C:/data/Ximena/Gonda | I11: lcmethodpath | J11: lcmethodshort_dry | K11: lcmethodfilename | L11: =IF(LEN(Experiment!AG11)=0,"",Experiment!AG11) -> 1 | M11: 3
A12: 11 | B12: =IF(LEN(Experiment!AE12)=0,"",Experiment!AE12) -> Condition | C12: =IF(LEN(Experiment!AF12)=0,"",Experiment!AF12) -> 11 | D12: D:/data/Ximena/Gonda0821 | E12: D:/method/Chao/something | F12: DIA20ng | G12: DIA20ng | H12: C:/data/Ximena/Gonda | I12: lcmethodpath | J12: lcmethodshort_dry | K12: lcmethodfilename | L12: =IF(LEN(Experiment!AG12)=0,"",Experiment!AG12) -> 1 | M12: 3
A13: 12 | B13: =IF(LEN(Experiment!AE13)=0,"",Experiment!AE13) -> Condition | C13: =IF(LEN(Experiment!AF13)=0,"",Experiment!AF13) -> 12 | D13: D:/data/Ximena/Gonda0821 | E13: D:/method/Chao/something | F13: DIA20ng | G13: DIA20ng | H13: C:/data/Ximena/Gonda | I13: lcmethodpath | J13: lcmethodshort_dry | K13: lcmethodfilename | L13: =IF(LEN(Experiment!AG13)=0,"",Experiment!AG13) -> 1 | M13: 3
A14: 13 | B14: =IF(LEN(Experiment!AE14)=0,"",Experiment!AE14) -> Condition | C14: =IF(LEN(Experiment!AF14)=0,"",Experiment!AF14) -> 13 | D14: D:/data/Ximena/Gonda0821 | E14: D:/method/Chao/something | F14: DIA20ng | G14: DIA20ng | H14: C:/data/Ximena/Gonda | I14: lcmethodpath | J14: lcmethodshort_dry | K14: lcmethodfilename | L14: =IF(LEN(Experiment!AG14)=0,"",Experiment!AG14) -> 1 | M14: 3
A15: 14 | B15: =IF(LEN(Experiment!AE15)=0,"",Experiment!AE15) -> Condition | C15: =IF(LEN(Experiment!AF15)=0,"",Experiment!AF15) -> 14 | D15: D:/data/Ximena/Gonda0821 | E15: D:/method/Chao/something | F15: DIA20ng | G15: DIA20ng | H15: C:/data/Ximena/Gonda | I15: lcmethodpath | J15: lcmethodshort_dry | K15: lcmethodfilename | L15: =IF(LEN(Experiment!AG15)=0,"",Experiment!AG15) -> 1 | M15: 3
A16: 15 | B16: =IF(LEN(Experiment!AE16)=0,"",Experiment!AE16) -> Condition | C16: =IF(LEN(Experiment!AF16)=0,"",Experiment!AF16) -> 15 | D16: D:/data/Ximena/Gonda0821 | E16: D:/method/Chao/something | F16: DIA20ng | G16: DIA20ng | H16: C:/data/Ximena/Gonda | I16: lcmethodpath | J16: lcmethodshort_dry | K16: lcmethodfilename | L16: =IF(LEN(Experiment!AG16)=0,"",Experiment!AG16) -> 1 | M16: 3
A17: 16 | B17: =IF(LEN(Experiment!AE17)=0,"",Experiment!AE17) -> Condition | C17: =IF(LEN(Experiment!AF17)=0,"",Experiment!AF17) -> 16 | D17: D:/data/Ximena/Gonda0821 | E17: D:/method/Chao/something | F17: DIA20ng | G17: DIA20ng | H17: C:/data/Ximena/Gonda | I17: lcmethodpath | J17: lcmethodshort_dry | K17: lcmethodfilename | L17: =IF(LEN(Experiment!AG17)=0,"",Experiment!AG17) -> 1 | M17: 3
A18: 17 | B18: =IF(LEN(Experiment!AE18)=0,"",Experiment!AE18) -> Condition | C18: =IF(LEN(Experiment!AF18)=0,"",Experiment!AF18) -> 17 | D18: D:/data/Ximena/Gonda0821 | E18: D:/method/Chao/something | F18: DIA20ng | G18: DIA20ng | H18: C:/data/Ximena/Gonda | I18: lcmethodpath | J18: lcmethodshort_dry | K18: lcmethodfilename | L18: =IF(LEN(Experiment!AG18)=0,"",Experiment!AG18) -> 1 | M18: 3
A19: 18 | B19: =IF(LEN(Experiment!AE19)=0,"",Experiment!AE19) -> Condition | C19: =IF(LEN(Experiment!AF19)=0,"",Experiment!AF19) -> 18 | D19: D:/data/Ximena/Gonda0821 | E19: D:/method/Chao/something | F19: DIA20ng | G19: DIA20ng | H19: C:/data/Ximena/Gonda | I19: lcmethodpath | J19: lcmethodshort_dry | K19: lcmethodfilename | L19: =IF(LEN(Experiment!AG19)=0,"",Experiment!AG19) -> 1 | M19: 3
... A30: 29 | B30: =IF(LEN(Experiment!AE30)=0,"",Experiment!AE30) -> Condition | C30: =IF(LEN(Experiment!AF30)=0,"",Experiment!AF30) -> 29 | D30: D:/data/Ximena/Gonda0821 | E30: D:/method/Chao/something | F30: DIA20ng | G30: DIA20ng | H30: C:/data/Ximena/Gonda | I30: lcmethodpath | J30: lcmethodshort_dry | K30: lcmethodfilename | L30: =IF(LEN(Experiment!AG30)=0,"",Experiment!AG30) -> 1 | M30: 3
A31: 30 | B31: =IF(LEN(Experiment!AE31)=0,"",Experiment!AE31) -> QC | C31: =IF(LEN(Experiment!AF31)=0,"",Experiment!AF31) -> 30 | D31: D:/data/Ximena/Gonda0821 | E31: D:/method/Chao/something | F31: DIA20ng | G31: DIA20ng | H31: C:/data/Ximena/Gonda | I31: lcmethodpath | J31: lcmethodshort_dry | K31: lcmethodfilename | L31: =IF(LEN(Experiment!AG31)=0,"",Experiment!AG31) -> 1 | M31: all | N31: 1 | O31: 1 | P31: 1
A32: 31 | B32: =IF(LEN(Experiment!AE32)=0,"",Experiment!AE32) -> WetQC | C32: =IF(LEN(Experiment!AF32)=0,"",Experiment!AF32) -> QC | D32: D:/data/Ximena/Gonda0821 | E32: D:/method/Chao/something | F32: DIA20ng | G32: DIA20ng | H32: C:/data/Ximena/Gonda | I32: lcmethodpath | J32: lcmethodshort_dry | K32: lcmethodfilename | L32: =IF(LEN(Experiment!AG32)=0,"",Experiment!AG32) -> 3 | M32: all | N32: 4 | O32: 5 | P32: 2
A33: 32 | B33: =IF(LEN(Experiment!AE33)=0,"",Experiment!AE33) -> TrueBlank | C33: =IF(LEN(Experiment!AF33)=0,"",Experiment!AF33) -> TrueBlank | D33: D:/data/Ximena/Gonda0821 | E33: D:/method/Chao/something | F33: DIA20ng | G33: DIA20ng | H33: C:/data/Ximena/Gonda | I33: lcmethodpath | J33: lcmethodshort_dry | K33: lcmethodfilename | L33: =IF(LEN(Experiment!AG33)=0,"",Experiment!AG33) -> 1 | M33: all | N33: 4 | O33: 5 | P33: 2
A34: 33 | B34: Condition | C34: =IF(LEN(Experiment!AF34)=0,"",Experiment!AF34) -> 67 | D34: D:/data/Ximena/Gonda0821 | E34: D:/method/Chao/something | F34: DIA20ng | G34: DIA20ng | H34: C:/data/Ximena/Gonda | I34: lcmethodpath | J34: lcmethodshort_dry | K34: lcmethodfilename | L34: =IF(LEN(Experiment!AG34)=0,"",Experiment!AG34) -> 1 | M34: 3
A35: 34 | B35: =IF(LEN(Experiment!AE35)=0,"",Experiment!AE35) | C35: =IF(LEN(Experiment!AF35)=0,"",Experiment!AF35) | L35: =IF(LEN(Experiment!AG35)=0,"",Experiment!AG35)
A36: 35 | B36: =IF(LEN(Experiment!AE36)=0,"",Experiment!AE36) | C36: =IF(LEN(Experiment!AF36)=0,"",Experiment!AF36) | L36: =IF(LEN(Experiment!AG36)=0,"",Experiment!AG36)
A37: 36 | B37: =IF(LEN(Experiment!AE37)=0,"",Experiment!AE37) | C37: =IF(LEN(Experiment!AF37)=0,"",Experiment!AF37) | L37: =IF(LEN(Experiment!AG37)=0,"",Experiment!AG37)
A38: 37 | B38: =IF(LEN(Experiment!AE38)=0,"",Experiment!AE38) | C38: =IF(LEN(Experiment!AF38)=0,"",Experiment!AF38) | L38: =IF(LEN(Experiment!AG38)=0,"",Experiment!AG38)
A39: 38 | B39: =IF(LEN(Experiment!AE39)=0,"",Experiment!AE39) | C39: =IF(LEN(Experiment!AF39)=0,"",Experiment!AF39) | L39: =IF(LEN(Experiment!AG39)=0,"",Experiment!AG39)
A40: 39 | B40: =IF(LEN(Experiment!AE40)=0,"",Experiment!AE40) | C40: =IF(LEN(Experiment!AF40)=0,"",Experiment!AF40) | L40: =IF(LEN(Experiment!AG40)=0,"",Experiment!AG40)
A41: 40 | B41: =IF(LEN(Experiment!AE41)=0,"",Experiment!AE41) | C41: =IF(LEN(Experiment!AF41)=0,"",Experiment!AF41) | L41: =IF(LEN(Experiment!AG41)=0,"",Experiment!AG41)
A42: 41 | B42: =IF(LEN(Experiment!AE42)=0,"",Experiment!AE42) | C42: =IF(LEN(Experiment!AF42)=0,"",Experiment!AF42) | L42: =IF(LEN(Experiment!AG42)=0,"",Experiment!AG42)
A43: 42 | B43: =IF(LEN(Experiment!AE43)=0,"",Experiment!AE43) | C43: =IF(LEN(Experiment!AF43)=0,"",Experiment!AF43) | L43: =IF(LEN(Experiment!AG43)=0,"",Experiment!AG43)
A44: 43 | B44: =IF(LEN(Experiment!AE44)=0,"",Experiment!AE44) | C44: =IF(LEN(Experiment!AF44)=0,"",Experiment!AF44) | L44: =IF(LEN(Experiment!AG44)=0,"",Experiment!AG44)
A45: 44 | B45: =IF(LEN(Experiment!AE45)=0,"",Experiment!AE45) | C45: =IF(LEN(Experiment!AF45)=0,"",Experiment!AF45) | L45: =IF(LEN(Experiment!AG45)=0,"",Experiment!AG45)
A46: 45 | B46: =IF(LEN(Experiment!AE46)=0,"",Experiment!AE46) | C46: =IF(LEN(Experiment!AF46)=0,"",Experiment!AF46) | L46: =IF(LEN(Experiment!AG46)=0,"",Experiment!AG46)
... A50: 49 | B50: =IF(LEN(Experiment!AE50)=0,"",Experiment!AE50) | C50: =IF(LEN(Experiment!AF50)=0,"",Experiment!AF50) | L50: =IF(LEN(Experiment!AG50)=0,"",Experiment!AG50)
A51: 50 | B51: =IF(LEN(Experiment!AE51)=0,"",Experiment!AE51) | C51: =IF(LEN(Experiment!AF51)=0,"",Experiment!AF51)
