Workbook

Sheet User
A1: Name: | B1: Test 1 | AD1: Number: | AE1: Well Type: | AF1: Condition: | AG1: Samples/Well: | AH1: Notes (not used):
A2: Notebook Code: | B2: Test 1 | AD2: 1 | AE2: Condition | AF2: condA | AG2: 1
A3: Experiment Name: | B3: Test 1 | AD3: 2 | AE3: Condition | AF3: condB | AG3: 1 | AU3: "Before" indicates that this number of the condition selected should be run before all of the samples. Likewise with "after" referring to after all samples are run. "Between" counts indicate the number runs of this condition to be put into blocks that will be inserted at intervals between blocks of sample.
AD4: 3 | AE4: Condition | AF4: condC | AG4: 1 | AI4: Force even blocks? | AK4: Doesn't use all wells in order to create blocks of uniform size.
A5: Plate color: | B5: Plate name: | D5: Plate 1 | E5: 1 | F5: 2 | G5: 3 | H5: 4 | I5: 5 | J5: 6 | K5: 7 | L5: 8 | M5: 9 | N5: 10 | O5: 11 | P5: 12 | Q5: 13 | R5: 14 | S5: 15 | T5: 16 | U5: 17 | V5: 18 | W5: 19 | X5: 20 | Y5: 21 | Z5: 22 | AA5: 23 | AB5: 24 | AD5: 4 | AE5: Condition | AF5: condD | AG5: 1 | AI5: TrueBlank Well Location: | AK5: Provide one location of an empty well on any plate (e.g. RA1)
A6: R | B6: Plate 1 | D6: A | AD6: 5 | AE6: Condition | AF6: condE | AG6: 1
D7: B | F7: 1 | G7: 1 | H7: 1 | I7: 1 | J7: 1 | K7: 1 | L7: 1 | M7: 1 | N7: 1 | O7: 1 | P7: 1 | Q7: 1 | R7: 1 | S7: 1 | T7: 1 | U7: 1 | V7: 1 | W7: 1 | X7: 1 | Y7: 1 | Z7: 1 | AA7: 1 | AD7: 6 | AE7: Condition | AF7: condF | AG7: 1
D8: C | F8: 1 | G8: 1 | H8: 1 | I8: 1 | J8: 1 | K8: 1 | L8: 1 | M8: 1 | N8: 1 | O8: 1 | P8: 1 | Q8: 1 | R8: 1 | S8: 1 | T8: 1 | U8: 1 | V8: 1 | W8: 1 | X8: 1 | Y8: 1 | Z8: 1 | AA8: 1 | AD8: 7 | AE8: Condition | AF8: condG | AG8: 1 | AI8: Experiment One Range: | AJ8: All | AK8: Either write "All" for experiment one or a number range corresponding to the Number column (AD). For example, "1-5" and "6-10".
B9: Solvent Vials | D9: D | F9: 2 | G9: 2 | H9: 2 | I9: 2 | J9: 2 | K9: 2 | L9: 2 | M9: 2 | N9: 2 | O9: 2 | P9: 2 | Q9: 2 | R9: 2 | S9: 2 | T9: 2 | U9: 2 | V9: 2 | W9: 2 | X9: 2 | Y9: 2 | Z9: 2 | AA9: 2 | AD9: 8 | AE9: QC | AF9: qc | AG9: 1 | AI9: Experiment Two Range:
A10: 1 | D10: E | F10: 2 | G10: 2 | H10: 2 | I10: 2 | J10: 2 | K10: 2 | L10: 2 | M10: 2 | N10: 2 | O10: 2 | P10: 2 | Q10: 2 | R10: 2 | S10: 2 | T10: 2 | U10: 2 | V10: 2 | W10: 2 | X10: 2 | Y10: 2 | Z10: 2 | AA10: 2 | AD10: 9 | AE10: Blank | AF10: dm | AG10: 1 | AI10: Are libraries the same between experiments? | AJ10: Yes
A11: 2 | D11: F | F11: 3 | G11: 3 | H11: 3 | I11: 3 | J11: 3 | K11: 3 | L11: 3 | M11: 3 | N11: 3 | O11: 3 | P11: 3 | Q11: 3 | R11: 3 | S11: 3 | T11: 3 | U11: 3 | V11: 3 | W11: 3 | X11: 3 | Y11: 3 | Z11: 3 | AA11: 3 | AD11: 10 | AE11: Library | AF11: lib | AG11: 1
A12: 3 | D12: G | F12: 3 | G12: 3 | H12: 3 | I12: 3 | J12: 3 | K12: 3 | L12: 3 | M12: 3 | N12: 3 | O12: 3 | P12: 3 | Q12: 3 | R12: 3 | S12: 3 | T12: 3 | U12: 3 | V12: 3 | W12: 3 | X12: 3 | Y12: 3 | Z12: 3 | AA12: 3 | AD12: 11 | AE12: SystemValidation | AF12: sysqc | AG12: 1
A13: 4 | D13: H | F13: 4 | G13: 4 | H13: 4 | I13: 4 | J13: 4 | K13: 4 | L13: 4 | M13: 4 | N13: 4 | O13: 4 | P13: 4 | Q13: 4 | R13: 4 | S13: 4 | T13: 4 | U13: 4 | V13: 4 | W13: 4 | X13: 4 | Y13: 4 | Z13: 4 | AA13: 4 | AD13: 12
A14: 5 | D14: I | F14: 4 | G14: 4 | H14: 4 | I14: 4 | J14: 4 | K14: 4 | L14: 4 | M14: 4 | N14: 4 | O14: 4 | P14: 4 | Q14: 4 | R14: 4 | S14: 4 | T14: 4 | U14: 4 | V14: 4 | W14: 4 | X14: 4 | Y14: 4 | Z14: 4 | AA14: 4 | AD14: 13
D15: J | F15: 5 | G15: 5 | H15: 5 | I15: 5 | J15: 5 | K15: 5 | L15: 5 | M15: 5 | N15: 5 | O15: 5 | P15: 5 | Q15: 5 | R15: 5 | S15: 5 | T15: 5 | U15: 5 | V15: 5 | W15: 5 | X15: 5 | Y15: 5 | Z15: 5 | AA15: 5 | AD15: 14
D16: K | F16: 5 | G16: 5 | H16: 5 | I16: 5 | J16: 5 | K16: 5 | L16: 5 | M16: 5 | N16: 5 | O16: 5 | P16: 5 | Q16: 5 | R16: 5 | S16: 5 | T16: 5 | U16: 5 | V16: 5 | W16: 5 | X16: 5 | Y16: 5 | Z16: 5 | AA16: 5 | AD16: 15
D17: L | F17: 6 | G17: 6 | H17: 6 | I17: 6 | J17: 6 | K17: 6 | L17: 6 | M17: 6 | N17: 6 | O17: 6 | P17: 6 | Q17: 6 | R17: 6 | S17: 6 | T17: 6 | U17: 6 | V17: 6 | W17: 6 | X17: 6 | Y17: 6 | Z17: 6 | AA17: 6 | AD17: 16
D18: M | F18: 6 | G18: 6 | H18: 6 | I18: 6 | J18: 6 | K18: 6 | L18: 6 | M18: 6 | N18: 6 | O18: 6 | P18: 6 | Q18: 6 | R18: 6 | S18: 6 | T18: 6 | U18: 6 | V18: 6 | W18: 6 | X18: 6 | Y18: 6 | Z18: 6 | AA18: 6 | AD18: 17
D19: N | F19: 7 | G19: 7 | H19: 7 | I19: 7 | J19: 7 | K19: 7 | L19: 7 | M19: 7 | N19: 7 | O19: 7 | P19: 7 | Q19: 7 | R19: 7 | S19: 7 | T19: 7 | U19: 7 | V19: 7 | W19: 7 | X19: 7 | Y19: 7 | Z19: 7 | AA19: 7 | AD19: 18
D20: O | F20: 7 | G20: 7 | H20: 7 | I20: 7 | J20: 7 | K20: 7 | L20: 7 | M20: 7 | N20: 7 | O20: 7 | P20: 7 | Q20: 7 | R20: 7 | S20: 7 | T20: 7 | U20: 7 | V20: 7 | W20: 7 | X20: 7 | Y20: 7 | Z20: 7 | AA20: 7 | AD20: 19
D21: P | AD21: 20
AD22: 21
A23: Plate color: | B23: Plate name: | D23: Plate 2 | E23: 1 | F23: 2 | G23: 3 | H23: 4 | I23: 5 | J23: 6 | K23: 7 | L23: 8 | M23: 9 | N23: 10 | O23: 11 | P23: 12 | Q23: 13 | R23: 14 | S23: 15 | T23: 16 | U23: 17 | V23: 18 | W23: 19 | X23: 20 | Y23: 21 | Z23: 22 | AA23: 23 | AB23: 24 | AD23: 22
A24: G | B24: Plate 2 | D24: A | AD24: 23
D25: B | F25: 8 | G25: 8 | H25: 8 | I25: 8 | J25: 8 | K25: 8 | L25: 8 | M25: 8 | N25: 8 | O25: 8 | P25: 8 | Q25: 8 | R25: 8 | S25: 8 | T25: 8 | U25: 8 | V25: 8 | W25: 8 | X25: 8 | Y25: 8 | Z25: 8 | AA25: 8 | AD25: 24
D26: C | F26: 8 | G26: 8 | H26: 8 | I26: 8 | J26: 8 | K26: 8 | L26: 8 | M26: 8 | N26: 8 | O26: 8 | P26: 8 | Q26: 8 | R26: 8 | S26: 8 | T26: 8 | U26: 8 | V26: 8 | W26: 8 | X26: 8 | Y26: 8 | Z26: 8 | AA26: 8 | AD26: 25
B27: Solvent Vials | D27: D | F27: 8 | G27: 8 | H27: 8 | I27: 8 | J27: 8 | K27: 8 | L27: 8 | M27: 8 | N27: 8 | O27: 8 | P27: 8 | Q27: 8 | R27: 8 | S27: 8 | T27: 8 | U27: 8 | V27: 8 | W27: 8 | X27: 8 | Y27: 8 | Z27: 8 | AA27: 8 | AD27: 26
A28: 1 | D28: E | F28: 8 | G28: 8 | H28: 8 | I28: 8 | J28: 8 | K28: 8 | L28: 8 | M28: 8 | N28: 8 | O28: 8 | P28: 8 | Q28: 8 | R28: 8 | S28: 8 | T28: 8 | U28: 8 | V28: 8 | W28: 8 | X28: 8 | Y28: 8 | Z28: 8 | AA28: 8 | AD28: 27
A29: 2 | D29: F | F29: 9 | G29: 9 | H29: 9 | I29: 9 | J29: 9 | K29: 9 | L29: 9 | M29: 9 | N29: 9 | O29: 9 | P29: 9 | Q29: 9 | R29: 9 | S29: 9 | T29: 9 | U29: 9 | V29: 9 | W29: 9 | X29: 9 | Y29: 9 | Z29: 9 | AA29: 9 | AD29: 28
A30: 3 | D30: G | F30: 9 | G30: 9 | H30: 9 | I30: 9 | J30: 9 | K30: 9 | L30: 9 | M30: 9 | N30: 9 | O30: 9 | P30: 9 | Q30: 9 | R30: 9 | S30: 9 | T30: 9 | U30: 9 | V30: 9 | W30: 9 | X30: 9 | Y30: 9 | Z30: 9 | AA30: 9 | AD30: 29
A31: 4 | D31: H | F31: 9 | G31: 9 | H31: 9 | I31: 9 | J31: 9 | K31: 9 | L31: 9 | M31: 9 | N31: 9 | O31: 9 | P31: 9 | Q31: 9 | R31: 9 | S31: 9 | T31: 9 | U31: 9 | V31: 9 | W31: 9 | X31: 9 | Y31: 9 | Z31: 9 | AA31: 9 | AD31: 30
A32: 5 | D32: I | F32: 9 | G32: 9 | H32: 9 | I32: 9 | J32: 9 | K32: 9 | L32: 9 | M32: 9 | N32: 9 | O32: 9 | P32: 9 | Q32: 9 | R32: 9 | S32: 9 | T32: 9 | U32: 9 | V32: 9 | W32: 9 | X32: 9 | Y32: 9 | Z32: 9 | AA32: 9 | AD32: 31
D33: J | F33: 10 | G33: 10 | H33: 10 | I33: 10 | J33: 10 | K33: 10 | L33: 10 | M33: 10 | N33: 10 | O33: 10 | P33: 10 | Q33: 10 | R33: 10 | S33: 10 | T33: 10 | U33: 10 | V33: 10 | W33: 10 | X33: 10 | Y33: 10 | Z33: 10 | AA33: 10 | AD33: 32
D34: K | F34: 10 | G34: 10 | H34: 10 | I34: 10 | J34: 10 | K34: 10 | L34: 10 | M34: 10 | N34: 10 | O34: 10 | P34: 10 | Q34: 10 | R34: 10 | S34: 10 | T34: 10 | U34: 10 | V34: 10 | W34: 10 | X34: 10 | Y34: 10 | Z34: 10 | AA34: 10 | AD34: 33
D35: L | F35: 10 | G35: 10 | H35: 10 | I35: 10 | J35: 10 | K35: 10 | L35: 10 | M35: 10 | N35: 10 | O35: 10 | P35: 10 | Q35: 10 | R35: 10 | S35: 10 | T35: 10 | U35: 10 | V35: 10 | W35: 10 | X35: 10 | Y35: 10 | Z35: 10 | AA35: 10 | AD35: 34
D36: M | F36: 10 | G36: 10 | H36: 10 | I36: 10 | J36: 10 | K36: 10 | L36: 10 | M36: 10 | N36: 10 | O36: 10 | P36: 10 | Q36: 10 | R36: 10 | S36: 10 | T36: 10 | U36: 10 | V36: 10 | W36: 10 | X36: 10 | Y36: 10 | Z36: 10 | AA36: 10 | AD36: 35
D37: N | F37: 11 | G37: 11 | H37: 11 | I37: 11 | J37: 11 | K37: 11 | L37: 11 | M37: 11 | N37: 11 | O37: 11 | P37: 11 | Q37: 11 | R37: 11 | S37: 11 | T37: 11 | U37: 11 | V37: 11 | W37: 11 | X37: 11 | Y37: 11 | Z37: 11 | AA37: 11 | AD37: 36
D38: O | F38: 11 | G38: 11 | H38: 11 | I38: 11 | J38: 11 | K38: 11 | L38: 11 | M38: 11 | N38: 11 | O38: 11 | P38: 11 | Q38: 11 | R38: 11 | S38: 11 | T38: 11 | U38: 11 | V38: 11 | W38: 11 | X38: 11 | Y38: 11 | Z38: 11 | AA38: 11 | AD38: 37
D39: P | AD39: 38
AD40: 39
...

Sheet Manager
A1: Number: | B1: Well Type: | C1: Condition: | D1: MS DataPath: | E1: MS MethodPath: | F1: MS method: | G1: MS method file name: | H1: LC DataPath | I1: LC MethodPath: | J1: LC method: | K1: LC method file name: | L1: Samples/Well: | M1: Number of sample to run: | N1: Injection volume: | O1: Nonsample before: | P1: Nonsample after: | Q1: Nonsample between: | R1: System configuration:
A2: 1 | B2: =IF(LEN(User!AE2)=0,"",User!AE2) -> Condition | C2: =IF(LEN(User!AF2)=0,"",User!AF2) -> condA | D2: mspath/datapath | E2: mspath/methodpath | F2: msmethod | G2: 2ng | H2: lcpath/datapath | I2: lcpath/methodpath | J2: lcmethod | K2: 2ng | L2: =IF(LEN(User!AG2)=0,"",User!AG2) -> 1 | R2: Analytical Columns: | S2: 1 column
A3: 2 | B3: =IF(LEN(User!AE3)=0,"",User!AE3) -> Condition | C3: =IF(LEN(User!AF3)=0,"",User!AF3) -> condB | D3: mspath/datapath | E3: mspath/methodpath | F3: msmethod | G3: 2ng | H3: lcpath/datapath | I3: lcpath/methodpath | J3: lcmethod | K3: 2ng | L3: =IF(LEN(User!AG3)=0,"",User!AG3) -> 1 | R3: For 2 column, "ChannelA_" or "ChannelB_" is added before column K (LC method file name)
A4: 3 | B4: =IF(LEN(User!AE4)=0,"",User!AE4) -> Condition | C4: =IF(LEN(User!AF4)=0,"",User!AF4) -> condC | D4: mspath/datapath | E4: mspath/methodpath | F4: msmethod | G4: 2ng | H4: lcpath/datapath | I4: lcpath/methodpath | J4: lcmethod | K4: 2ng | L4: =IF(LEN(User!AG4)=0,"",User!AG4) -> 1
A5: 4 | B5: =IF(LEN(User!AE5)=0,"",User!AE5) -> Condition | C5: =IF(LEN(User!AF5)=0,"",User!AF5) -> condD | D5: mspath/datapath | E5: mspath/methodpath | F5: msmethod | G5: 2ng | H5: lcpath/datapath | I5: lcpath/methodpath | J5: lcmethod | K5: 2ng | L5: =IF(LEN(User!AG5)=0,"",User!AG5) -> 1 | R5: Library runs placement: | S5: Before
A6: 5 | B6: =IF(LEN(User!AE6)=0,"",User!AE6) -> Condition | C6: =IF(LEN(User!AF6)=0,"",User!AF6) -> condE | D6: mspath/datapath | E6: mspath/methodpath | F6: msmethod | G6: 2ng | H6: lcpath/datapath | I6: lcpath/methodpath | J6: lcmethod | K6: 2ng | L6: =IF(LEN(User!AG6)=0,"",User!AG6) -> 1 | R6: Do Library runs come before or after the experiment?
A7: 6 | B7: =IF(LEN(User!AE7)=0,"",User!AE7) -> Condition | C7: =IF(LEN(User!AF7)=0,"",User!AF7) -> condF | D7: mspath/datapath | E7: mspath/methodpath | F7: msmethod | G7: 2ng | H7: lcpath/datapath | I7: lcpath/methodpath | J7: lcmethod | K7: 2ng | L7: =IF(LEN(User!AG7)=0,"",User!AG7) -> 1
A8: 7 | B8: =IF(LEN(User!AE8)=0,"",User!AE8) -> Condition | C8: =IF(LEN(User!AF8)=0,"",User!AF8) -> condG | D8: mspath/datapath | E8: mspath/methodpath | F8: msmethod | G8: 2ng | H8: lcpath/datapath | I8: lcpath/methodpath | J8: lcmethod | K8: 2ng | L8: =IF(LEN(User!AG8)=0,"",User!AG8) -> 1 | R8: Frequency of system validation (#): | S8: 10
A9: 8 | B9: =IF(LEN(User!AE9)=0,"",User!AE9) -> QC | C9: =IF(LEN(User!AF9)=0,"",User!AF9) -> qc | D9: mspath/datapath | E9: mspath/methodpath | F9: msmethod | G9: qc | H9: lcpath/datapath | I9: lcpath/methodpath | J9: lcmethod | K9: qc | L9: =IF(LEN(User!AG9)=0,"",User!AG9) -> 1 | O9: 2 | P9: 2 | Q9: 1 | R9: Frequency of QC (#): | S9: 10
A10: 9 | B10: =IF(LEN(User!AE10)=0,"",User!AE10) -> Blank | C10: =IF(LEN(User!AF10)=0,"",User!AF10) -> dm | D10: mspath/datapath | E10: mspath/methodpath | F10: msmethod | G10: blank | H10: lcpath/datapath | I10: lcpath/methodpath | J10: lcmethod | K10: blank | L10: =IF(LEN(User!AG10)=0,"",User!AG10) -> 1 | O10: 2 | P10: 2 | Q10: 1 | R10: NonCondition Ordering: QC->Blank->Trueblank
A11: 10 | B11: =IF(LEN(User!AE11)=0,"",User!AE11) -> Library | C11: =IF(LEN(User!AF11)=0,"",User!AF11) -> lib | D11: mspath/datapath | E11: mspath/methodpath | F11: msmethod | G11: lib | H11: lcpath/datapath | I11: lcpath/methodpath | J11: lcmethod | K11: lib | L11: =IF(LEN(User!AG11)=0,"",User!AG11) -> 1
A12: 11 | B12: =IF(LEN(User!AE12)=0,"",User!AE12) -> SystemValidation | C12: =IF(LEN(User!AF12)=0,"",User!AF12) -> sysqc | D12: mspath/datapath | E12: mspath/methodpath | F12: msmethod | G12: sysval | H12: lcpath/datapath | I12: lcpath/methodpath | J12: lcmethod | K12: sysval | L12: =IF(LEN(User!AG12)=0,"",User!AG12) -> 1 | R12: What LC system are you using? | S12: UltiMate3000
A13: 12 | B13: =IF(LEN(User!AE13)=0,"",User!AE13) | C13: =IF(LEN(User!AF13)=0,"",User!AF13) | L13: =IF(LEN(User!AG13)=0,"",User!AG13) | R13: This determines how the well location is denoted (RA1 vs R:A1)
A14: 13 | B14: =IF(LEN(User!AE14)=0,"",User!AE14) | C14: =IF(LEN(User!AF14)=0,"",User!AF14) | L14: =IF(LEN(User!AG14)=0,"",User!AG14) | R14: What MS system are you using? | S14: Thermo
A15: 14 | B15: =IF(LEN(User!AE15)=0,"",User!AE15) | C15: =IF(LEN(User!AF15)=0,"",User!AF15) | L15: =IF(LEN(User!AG15)=0,"",User!AG15) | R15: This determines if the run number is included at the end of each file name
A16: 15 | B16: =IF(LEN(User!AE16)=0,"",User!AE16) | C16: =IF(LEN(User!AF16)=0,"",User!AF16) | L16: =IF(LEN(User!AG16)=0,"",User!AG16)
A17: 16 | B17: =IF(LEN(User!AE17)=0,"",User!AE17) | C17: =IF(LEN(User!AF17)=0,"",User!AF17) | L17: =IF(LEN(User!AG17)=0,"",User!AG17)
A18: 17 | B18: =IF(LEN(User!AE18)=0,"",User!AE18) | C18: =IF(LEN(User!AF18)=0,"",User!AF18) | L18: =IF(LEN(User!AG18)=0,"",User!AG18)
A19: 18 | B19: =IF(LEN(User!AE19)=0,"",User!AE19) | C19: =IF(LEN(User!AF19)=0,"",User!AF19) | L19: =IF(LEN(User!AG19)=0,"",User!AG19)
A20: 19 | B20: =IF(LEN(User!AE20)=0,"",User!AE20) | C20: =IF(LEN(User!AF20)=0,"",User!AF20) | L20: =IF(LEN(User!AG20)=0,"",User!AG20)
A21: 20 | B21: =IF(LEN(User!AE21)=0,"",User!AE21) | C21: =IF(LEN(User!AF21)=0,"",User!AF21) | L21: =IF(LEN(User!AG21)=0,"",User!AG21)
A22: 21 | B22: =IF(LEN(User!AE22)=0,"",User!AE22) | C22: =IF(LEN(User!AF22)=0,"",User!AF22) | L22: =IF(LEN(User!AG22)=0,"",User!AG22)
A23: 22 | B23: =IF(LEN(User!AE23)=0,"",User!AE23) | C23: =IF(LEN(User!AF23)=0,"",User!AF23) | L23: =IF(LEN(User!AG23)=0,"",User!AG23)
A24: 23 | B24: =IF(LEN(User!AE24)=0,"",User!AE24) | C24: =IF(LEN(User!AF24)=0,"",User!AF24) | L24: =IF(LEN(User!AG24)=0,"",User!AG24)
A25: 24 | B25: =IF(LEN(User!AE25)=0,"",User!AE25) | C25: =IF(LEN(User!AF25)=0,"",User!AF25) | L25: =IF(LEN(User!AG25)=0,"",User!AG25)
A26: 25 | B26: =IF(LEN(User!AE26)=0,"",User!AE26) | C26: =IF(LEN(User!AF26)=0,"",User!AF26) | L26: =IF(LEN(User!AG26)=0,"",User!AG26)
A27: 26 | B27: =IF(LEN(User!AE27)=0,"",User!AE27) | C27: =IF(LEN(User!AF27)=0,"",User!AF27) | L27: =IF(LEN(User!AG27)=0,"",User!AG27)
... A50: 49 | B50: =IF(LEN(User!AE50)=0,"",User!AE50) | C50: =IF(LEN(User!AF50)=0,"",User!AF50) | L50: =IF(LEN(User!AG50)=0,"",User!AG50)
A51: 50 | B51: =IF(LEN(User!AE51)=0,"",User!AE51) | C51: =IF(LEN(User!AF51)=0,"",User!AF51)
